Workbook
Name AK_End: Dashboard!$H$7
Name AK_Start: Dashboard!$G$7
Name DayEnd: Dashboard!$B$8
Name DayHrs: Dashboard!$B$5
Name DayStart: Dashboard!$B$7
Name JM_End: Dashboard!$H$8
Name JM_Start: Dashboard!$G$8
Name LL_End: Dashboard!$H$5
Name LL_Start: Dashboard!$G$5
Name NightHrs: Dashboard!$B$6
Name StaffList: Dashboard!$D$4:$D$23
Name TB_End: Dashboard!$H$6
Name TB_Start: Dashboard!$G$6
Name TimeList: Dashboard!$K$5:$K$37
Name TP_End: Dashboard!$H$9
Name TP_Start: Dashboard!$G$9
Name TP2_End: Dashboard!$H$10
Name TP2_Start: Dashboard!$G$10
Name VisitHrs: Dashboard!$B$4

Sheet Patient Rota
A1: Patient Care Rota
A2: Starting 8th July 2026 · live consolidated view (edit on the client tabs)
A4: Date | B4: Lucy Levene | D4: Tom Bock | F4: Anita Klesch (24-Hour Coverage) | H4: Jeremy | J4: Test Patient | L4: Test Patient 2 (24h)
B5: AM | C5: PM | D5: AM | E5: PM | F5: Day (8am–8pm) | G5: Night (8pm–8am) | H5: AM | I5: PM | J5: AM | K5: PM | L5: Day (8am–8pm) | M5: Night (8pm–8am)
A6: ='Lucy Levene'!A5 -> 46211 | B6: =IF('Lucy Levene'!B5="","",'Lucy Levene'!B5) | C6: =IF('Lucy Levene'!D5="","",'Lucy Levene'!D5) | D6: =IF('Tom Bock'!B5="","",'Tom Bock'!B5) | E6: =IF('Tom Bock'!D5="","",'Tom Bock'!D5) | F6: =IF('Anita Klesch'!B5="","",'Anita Klesch'!B5) -> Naresh | G6: =IF('Anita Klesch'!C5="","",'Anita Klesch'!C5) -> Maica | H6: =IF(Jeremy!B5="","",Jeremy!B5) | I6: =IF(Jeremy!D5="","",Jeremy!D5) | J6: =IF('Test Patient'!B5="","",'Test Patient'!B5) | K6: =IF('Test Patient'!D5="","",'Test Patient'!D5) | L6: =IF('Test Patient 2'!B5="","",'Test Patient 2'!B5) | M6: =IF('Test Patient 2'!C5="","",'Test Patient 2'!C5)
A7: ='Lucy Levene'!A6 -> 46212 | B7: =IF('Lucy Levene'!B6="","",'Lucy Levene'!B6) | C7: =IF('Lucy Levene'!D6="","",'Lucy Levene'!D6) -> Roderick | D7: =IF('Tom Bock'!B6="","",'Tom Bock'!B6) | E7: =IF('Tom Bock'!D6="","",'Tom Bock'!D6) | F7: =IF('Anita Klesch'!B6="","",'Anita Klesch'!B6) -> Naresh | G7: =IF('Anita Klesch'!C6="","",'Anita Klesch'!C6) -> Maica | H7: =IF(Jeremy!B6="","",Jeremy!B6) | I7: =IF(Jeremy!D6="","",Jeremy!D6) | J7: =IF('Test Patient'!B6="","",'Test Patient'!B6) | K7: =IF('Test Patient'!D6="","",'Test Patient'!D6) | L7: =IF('Test Patient 2'!B6="","",'Test Patient 2'!B6) | M7: =IF('Test Patient 2'!C6="","",'Test Patient 2'!C6)
A8: ='Lucy Levene'!A7 -> 46213 | B8: =IF('Lucy Levene'!B7="","",'Lucy Levene'!B7) -> Billie | C8: =IF('Lucy Levene'!D7="","",'Lucy Levene'!D7) -> Billie | D8: =IF('Tom Bock'!B7="","",'Tom Bock'!B7) | E8: =IF('Tom Bock'!D7="","",'Tom Bock'!D7) | F8: =IF('Anita Klesch'!B7="","",'Anita Klesch'!B7) -> Rochelle | G8: =IF('Anita Klesch'!C7="","",'Anita Klesch'!C7) -> Naresh | H8: =IF(Jeremy!B7="","",Jeremy!B7) | I8: =IF(Jeremy!D7="","",Jeremy!D7) | J8: =IF('Test Patient'!B7="","",'Test Patient'!B7) | K8: =IF('Test Patient'!D7="","",'Test Patient'!D7) | L8: =IF('Test Patient 2'!B7="","",'Test Patient 2'!B7) | M8: =IF('Test Patient 2'!C7="","",'Test Patient 2'!C7)
A9: ='Lucy Levene'!A8 -> 46214 | B9: =IF('Lucy Levene'!B8="","",'Lucy Levene'!B8) -> Roderick | C9: =IF('Lucy Levene'!D8="","",'Lucy Levene'!D8) -> Roderick | D9: =IF('Tom Bock'!B8="","",'Tom Bock'!B8) | E9: =IF('Tom Bock'!D8="","",'Tom Bock'!D8) | F9: =IF('Anita Klesch'!B8="","",'Anita Klesch'!B8) -> Rochelle | G9: =IF('Anita Klesch'!C8="","",'Anita Klesch'!C8) -> Naresh | H9: =IF(Jeremy!B8="","",Jeremy!B8) | I9: =IF(Jeremy!D8="","",Jeremy!D8) | J9: =IF('Test Patient'!B8="","",'Test Patient'!B8) | K9: =IF('Test Patient'!D8="","",'Test Patient'!D8) | L9: =IF('Test Patient 2'!B8="","",'Test Patient 2'!B8) | M9: =IF('Test Patient 2'!C8="","",'Test Patient 2'!C8)
A10: ='Lucy Levene'!A9 -> 46215 | B10: =IF('Lucy Levene'!B9="","",'Lucy Levene'!B9) -> Roderick | C10: =IF('Lucy Levene'!D9="","",'Lucy Levene'!D9) -> Roderick | D10: =IF('Tom Bock'!B9="","",'Tom Bock'!B9) -> Meseret | E10: =IF('Tom Bock'!D9="","",'Tom Bock'!D9) | F10: =IF('Anita Klesch'!B9="","",'Anita Klesch'!B9) -> Rochelle | G10: =IF('Anita Klesch'!C9="","",'Anita Klesch'!C9) -> Naresh | H10: =IF(Jeremy!B9="","",Jeremy!B9) | I10: =IF(Jeremy!D9="","",Jeremy!D9) | J10: =IF('Test Patient'!B9="","",'Test Patient'!B9) | K10: =IF('Test Patient'!D9="","",'Test Patient'!D9) | L10: =IF('Test Patient 2'!B9="","",'Test Patient 2'!B9) | M10: =IF('Test Patient 2'!C9="","",'Test Patient 2'!C9)
A11: ='Lucy Levene'!A10 -> 46216 | B11: Billie | C11: =IF('Lucy Levene'!D10="","",'Lucy Levene'!D10) -> Roderick | D11: =IF('Tom Bock'!B10="","",'Tom Bock'!B10) | E11: =IF('Tom Bock'!D10="","",'Tom Bock'!D10) | F11: =IF('Anita Klesch'!B10="","",'Anita Klesch'!B10) -> Ruth | G11: =IF('Anita Klesch'!C10="","",'Anita Klesch'!C10) -> Maica | H11: =IF(Jeremy!B10="","",Jeremy!B10) | I11: =IF(Jeremy!D10="","",Jeremy!D10) | J11: =IF('Test Patient'!B10="","",'Test Patient'!B10) | K11: =IF('Test Patient'!D10="","",'Test Patient'!D10) | L11: =IF('Test Patient 2'!B10="","",'Test Patient 2'!B10) | M11: =IF('Test Patient 2'!C10="","",'Test Patient 2'!C10)
A12: ='Lucy Levene'!A11 -> 46217 | B12: Roderick | C12: Roderick | D12: =IF('Tom Bock'!B11="","",'Tom Bock'!B11) | E12: =IF('Tom Bock'!D11="","",'Tom Bock'!D11) | F12: Naresh | G12: =IF('Anita Klesch'!C11="","",'Anita Klesch'!C11) -> Maica | H12: =IF(Jeremy!B11="","",Jeremy!B11) | I12: =IF(Jeremy!D11="","",Jeremy!D11) | J12: =IF('Test Patient'!B11="","",'Test Patient'!B11) | K12: =IF('Test Patient'!D11="","",'Test Patient'!D11) | L12: =IF('Test Patient 2'!B11="","",'Test Patient 2'!B11) | M12: =IF('Test Patient 2'!C11="","",'Test Patient 2'!C11)
A13: ='Lucy Levene'!A12 -> 46218 | B13: Rochelle | C13: Roderick | D13: =IF('Tom Bock'!B12="","",'Tom Bock'!B12) | E13: =IF('Tom Bock'!D12="","",'Tom Bock'!D12) | F13: =IF('Anita Klesch'!B12="","",'Anita Klesch'!B12) -> Naresh | G13: =IF('Anita Klesch'!C12="","",'Anita Klesch'!C12) -> Maica | H13: =IF(Jeremy!B12="","",Jeremy!B12) | I13: =IF(Jeremy!D12="","",Jeremy!D12) | J13: =IF('Test Patient'!B12="","",'Test Patient'!B12) | K13: =IF('Test Patient'!D12="","",'Test Patient'!D12) | L13: =IF('Test Patient 2'!B12="","",'Test Patient 2'!B12) | M13: =IF('Test Patient 2'!C12="","",'Test Patient 2'!C12)
A14: ='Lucy Levene'!A13 -> 46219 | B14: Roderick | C14: Roderick | D14: =IF('Tom Bock'!B13="","",'Tom Bock'!B13) | E14: =IF('Tom Bock'!D13="","",'Tom Bock'!D13) | F14: =IF('Anita Klesch'!B13="","",'Anita Klesch'!B13) -> Naresh | G14: =IF('Anita Klesch'!C13="","",'Anita Klesch'!C13) -> Maica | H14: =IF(Jeremy!B13="","",Jeremy!B13) | I14: =IF(Jeremy!D13="","",Jeremy!D13) | J14: =IF('Test Patient'!B13="","",'Test Patient'!B13) | K14: =IF('Test Patient'!D13="","",'Test Patient'!D13) | L14: =IF('Test Patient 2'!B13="","",'Test Patient 2'!B13) | M14: =IF('Test Patient 2'!C13="","",'Test Patient 2'!C13)
A15: ='Lucy Levene'!A14 -> 46220 | B15: Meseret | C15: Roderick | D15: =IF('Tom Bock'!B14="","",'Tom Bock'!B14) | E15: =IF('Tom Bock'!D14="","",'Tom Bock'!D14) | F15: Veronica | G15: =IF('Anita Klesch'!C14="","",'Anita Klesch'!C14) -> Maica | H15: =IF(Jeremy!B14="","",Jeremy!B14) | I15: =IF(Jeremy!D14="","",Jeremy!D14) | J15: =IF('Test Patient'!B14="","",'Test Patient'!B14) | K15: =IF('Test Patient'!D14="","",'Test Patient'!D14) | L15: =IF('Test Patient 2'!B14="","",'Test Patient 2'!B14) | M15: =IF('Test Patient 2'!C14="","",'Test Patient 2'!C14)
A16: ='Lucy Levene'!A15 -> 46221 | B16: Rochelle | C16: =IF('Lucy Levene'!D15="","",'Lucy Levene'!D15) -> Roderick | D16: =IF('Tom Bock'!B15="","",'Tom Bock'!B15) | E16: =IF('Tom Bock'!D15="","",'Tom Bock'!D15) | F16: Veronica | G16: Ruth | H16: =IF(Jeremy!B15="","",Jeremy!B15) | I16: =IF(Jeremy!D15="","",Jeremy!D15) | J16: =IF('Test Patient'!B15="","",'Test Patient'!B15) | K16: =IF('Test Patient'!D15="","",'Test Patient'!D15) | L16: =IF('Test Patient 2'!B15="","",'Test Patient 2'!B15) | M16: =IF('Test Patient 2'!C15="","",'Test Patient 2'!C15)
A17: ='Lucy Levene'!A16 -> 46222 | B17: Billie | C17: =IF('Lucy Levene'!D16="","",'Lucy Levene'!D16) -> Roderick | D17: =IF('Tom Bock'!B16="","",'Tom Bock'!B16) | E17: =IF('Tom Bock'!D16="","",'Tom Bock'!D16) | F17: Naresh | G17: Ruth | H17: =IF(Jeremy!B16="","",Jeremy!B16) | I17: =IF(Jeremy!D16="","",Jeremy!D16) | J17: =IF('Test Patient'!B16="","",'Test Patient'!B16) | K17: =IF('Test Patient'!D16="","",'Test Patient'!D16) | L17: =IF('Test Patient 2'!B16="","",'Test Patient 2'!B16) | M17: =IF('Test Patient 2'!C16="","",'Test Patient 2'!C16)
A18: ='Lucy Levene'!A17 -> 46223 | B18: Billie | C18: Roderick | D18: =IF('Tom Bock'!B17="","",'Tom Bock'!B17) | E18: =IF('Tom Bock'!D17="","",'Tom Bock'!D17) | F18: Naresh | G18: Maica | H18: =IF(Jeremy!B17="","",Jeremy!B17) | I18: =IF(Jeremy!D17="","",Jeremy!D17) | J18: =IF('Test Patient'!B17="","",'Test Patient'!B17) | K18: =IF('Test Patient'!D17="","",'Test Patient'!D17) | L18: =IF('Test Patient 2'!B17="","",'Test Patient 2'!B17) | M18: =IF('Test Patient 2'!C17="","",'Test Patient 2'!C17)
A19: ='Lucy Levene'!A18 -> 46224 | B19: Roderick | C19: Rochelle | D19: =IF('Tom Bock'!B18="","",'Tom Bock'!B18) | E19: =IF('Tom Bock'!D18="","",'Tom Bock'!D18) | H19: =IF(Jeremy!B18="","",Jeremy!B18) | I19: =IF(Jeremy!D18="","",Jeremy!D18) | J19: =IF('Test Patient'!B18="","",'Test Patient'!B18) | K19: =IF('Test Patient'!D18="","",'Test Patient'!D18) | L19: =IF('Test Patient 2'!B18="","",'Test Patient 2'!B18) | M19: =IF('Test Patient 2'!C18="","",'Test Patient 2'!C18)
A20: ='Lucy Levene'!A19 -> 46225 | B20: Rochelle | C20: Rochelle | D20: =IF('Tom Bock'!B19="","",'Tom Bock'!B19) | E20: =IF('Tom Bock'!D19="","",'Tom Bock'!D19) | H20: =IF(Jeremy!B19="","",Jeremy!B19) | I20: =IF(Jeremy!D19="","",Jeremy!D19) | J20: =IF('Test Patient'!B19="","",'Test Patient'!B19) | K20: =IF('Test Patient'!D19="","",'Test Patient'!D19) | L20: =IF('Test Patient 2'!B19="","",'Test Patient 2'!B19) | M20: =IF('Test Patient 2'!C19="","",'Test Patient 2'!C19)
A21: ='Lucy Levene'!A20 -> 46226 | B21: Rochelle | C21: Roderick | D21: =IF('Tom Bock'!B20="","",'Tom Bock'!B20) | E21: =IF('Tom Bock'!D20="","",'Tom Bock'!D20) | H21: =IF(Jeremy!B20="","",Jeremy!B20) | I21: =IF(Jeremy!D20="","",Jeremy!D20) | J21: =IF('Test Patient'!B20="","",'Test Patient'!B20) | K21: =IF('Test Patient'!D20="","",'Test Patient'!D20) | L21: =IF('Test Patient 2'!B20="","",'Test Patient 2'!B20) | M21: =IF('Test Patient 2'!C20="","",'Test Patient 2'!C20)
A22: ='Lucy Levene'!A21 -> 46227 | B22: Billie | C22: Roderick | D22: =IF('Tom Bock'!B21="","",'Tom Bock'!B21) | E22: =IF('Tom Bock'!D21="","",'Tom Bock'!D21) | H22: =IF(Jeremy!B21="","",Jeremy!B21) | I22: =IF(Jeremy!D21="","",Jeremy!D21) | J22: =IF('Test Patient'!B21="","",'Test Patient'!B21) | K22: =IF('Test Patient'!D21="","",'Test Patient'!D21) | L22: =IF('Test Patient 2'!B21="","",'Test Patient 2'!B21) | M22: =IF('Test Patient 2'!C21="","",'Test Patient 2'!C21)
A23: ='Lucy Levene'!A22 -> 46228 | B23: Roderick | C23: Billie | D23: =IF('Tom Bock'!B22="","",'Tom Bock'!B22) | E23: =IF('Tom Bock'!D22="","",'Tom Bock'!D22) | H23: =IF(Jeremy!B22="","",Jeremy!B22) | I23: =IF(Jeremy!D22="","",Jeremy!D22) | J23: =IF('Test Patient'!B22="","",'Test Patient'!B22) | K23: =IF('Test Patient'!D22="","",'Test Patient'!D22) | L23: =IF('Test Patient 2'!B22="","",'Test Patient 2'!B22) | M23: =IF('Test Patient 2'!C22="","",'Test Patient 2'!C22)
A24: ='Lucy Levene'!A23 -> 46229 | B24: Meseret | C24: Meseret | D24: =IF('Tom Bock'!B23="","",'Tom Bock'!B23) | E24: =IF('Tom Bock'!D23="","",'Tom Bock'!D23) | H24: =IF(Jeremy!B23="","",Jeremy!B23) | I24: =IF(Jeremy!D23="","",Jeremy!D23) | J24: =IF('Test Patient'!B23="","",'Test Patient'!B23) | K24: =IF('Test Patient'!D23="","",'Test Patient'!D23) | L24: =IF('Test Patient 2'!B23="","",'Test Patient 2'!B23) | M24: =IF('Test Patient 2'!C23="","",'Test Patient 2'!C23)
A25: ='Lucy Levene'!A24 -> 46230 | B25: Billie | C25: Roderick | D25: =IF('Tom Bock'!B24="","",'Tom Bock'!B24) | E25: =IF('Tom Bock'!D24="","",'Tom Bock'!D24) | H25: =IF(Jeremy!B24="","",Jeremy!B24) | I25: =IF(Jeremy!D24="","",Jeremy!D24) | J25: =IF('Test Patient'!B24="","",'Test Patient'!B24) | K25: =IF('Test Patient'!D24="","",'Test Patient'!D24) | L25: =IF('Test Patient 2'!B24="","",'Test Patient 2'!B24) | M25: =IF('Test Patient 2'!C24="","",'Test Patient 2'!C24)
A26: ='Lucy Levene'!A25 -> 46231 | B26: Rochelle | C26: Rochelle | D26: =IF('Tom Bock'!B25="","",'Tom Bock'!B25) | E26: =IF('Tom Bock'!D25="","",'Tom Bock'!D25) | H26: =IF(Jeremy!B25="","",Jeremy!B25) | I26: =IF(Jeremy!D25="","",Jeremy!D25) | J26: =IF('Test Patient'!B25="","",'Test Patient'!B25) | K26: =IF('Test Patient'!D25="","",'Test Patient'!D25) | L26: =IF('Test Patient 2'!B25="","",'Test Patient 2'!B25) | M26: =IF('Test Patient 2'!C25="","",'Test Patient 2'!C25)
A27: ='Lucy Levene'!A26 -> 46232 | B27: Billie | C27: Billie | D27: =IF('Tom Bock'!B26="","",'Tom Bock'!B26) | E27: =IF('Tom Bock'!D26="","",'Tom Bock'!D26) | H27: =IF(Jeremy!B26="","",Jeremy!B26) | I27: =IF(Jeremy!D26="","",Jeremy!D26) | J27: =IF('Test Patient'!B26="","",'Test Patient'!B26) | K27: =IF('Test Patient'!D26="","",'Test Patient'!D26) | L27: =IF('Test Patient 2'!B26="","",'Test Patient 2'!B26) | M27: =IF('Test Patient 2'!C26="","",'Test Patient 2'!C26)
A28: ='Lucy Levene'!A27 -> 46233 | B28: Roderick | C28: Roderick | D28: =IF('Tom Bock'!B27="","",'Tom Bock'!B27) | E28: =IF('Tom Bock'!D27="","",'Tom Bock'!D27) | H28: =IF(Jeremy!B27="","",Jeremy!B27) | I28: =IF(Jeremy!D27="","",Jeremy!D27) | J28: =IF('Test Patient'!B27="","",'Test Patient'!B27) | K28: =IF('Test Patient'!D27="","",'Test Patient'!D27) | L28: =IF('Test Patient 2'!B27="","",'Test Patient 2'!B27) | M28: =IF('Test Patient 2'!C27="","",'Test Patient 2'!C27)
A29: ='Lucy Levene'!A28 -> 46234 | B29: Roderick | C29: Rochelle | D29: =IF('Tom Bock'!B28="","",'Tom Bock'!B28) | E29: =IF('Tom Bock'!D28="","",'Tom Bock'!D28) | H29: =IF(Jeremy!B28="","",Jeremy!B28) | I29: =IF(Jeremy!D28="","",Jeremy!D28) | J29: =IF('Test Patient'!B28="","",'Test Patient'!B28) | K29: =IF('Test Patient'!D28="","",'Test Patient'!D28) | L29: =IF('Test Patient 2'!B28="","",'Test Patient 2'!B28) | M29: =IF('Test Patient 2'!C28="","",'Test Patient 2'!C28)
A30: ='Lucy Levene'!A29 -> 46235 | B30: Rochelle | C30: Roderick | D30: =IF('Tom Bock'!B29="","",'Tom Bock'!B29) | E30: =IF('Tom Bock'!D29="","",'Tom Bock'!D29) | H30: =IF(Jeremy!B29="","",Jeremy!B29) | I30: =IF(Jeremy!D29="","",Jeremy!D29) | J30: =IF('Test Patient'!B29="","",'Test Patient'!B29) | K30: =IF('Test Patient'!D29="","",'Test Patient'!D29) | L30: =IF('Test Patient 2'!B29="","",'Test Patient 2'!B29) | M30: =IF('Test Patient 2'!C29="","",'Test Patient 2'!C29)
A31: ='Lucy Levene'!A30 -> 46236 | B31: Meseret | C31: Meseret | D31: =IF('Tom Bock'!B30="","",'Tom Bock'!B30) | E31: =IF('Tom Bock'!D30="","",'Tom Bock'!D30) | F31: =IF('Anita Klesch'!B30="","",'Anita Klesch'!B30) | H31: =IF(Jeremy!B30="","",Jeremy!B30) | I31: =IF(Jeremy!D30="","",Jeremy!D30) | J31: =IF('Test Patient'!B30="","",'Test Patient'!B30) | K31: =IF('Test Patient'!D30="","",'Test Patient'!D30) | L31: =IF('Test Patient 2'!B30="","",'Test Patient 2'!B30) | M31: =IF('Test Patient 2'!C30="","",'Test Patient 2'!C30)
A32: ='Lucy Levene'!A31 -> 46237 | B32: =IF('Lucy Levene'!B31="","",'Lucy Levene'!B31) | C32: =IF('Lucy Levene'!D31="","",'Lucy Levene'!D31) | D32: =IF('Tom Bock'!B31="","",'Tom Bock'!B31) | E32: =IF('Tom Bock'!D31="","",'Tom Bock'!D31) | F32: =IF('Anita Klesch'!B31="","",'Anita Klesch'!B31) | G32: =IF('Anita Klesch'!C31="","",'Anita Klesch'!C31) | H32: =IF(Jeremy!B31="","",Jeremy!B31) | I32: =IF(Jeremy!D31="","",Jeremy!D31) | J32: =IF('Test Patient'!B31="","",'Test Patient'!B31) | K32: =IF('Test Patient'!D31="","",'Test Patient'!D31) | L32: =IF('Test Patient 2'!B31="","",'Test Patient 2'!B31) | M32: =IF('Test Patient 2'!C31="","",'Test Patient 2'!C31)
A33: ='Lucy Levene'!A32 -> 46238 | B33: =IF('Lucy Levene'!B32="","",'Lucy Levene'!B32) | C33: =IF('Lucy Levene'!D32="","",'Lucy Levene'!D32) | D33: =IF('Tom Bock'!B32="","",'Tom Bock'!B32) | E33: =IF('Tom Bock'!D32="","",'Tom Bock'!D32) | F33: =IF('Anita Klesch'!B32="","",'Anita Klesch'!B32) | G33: =IF('Anita Klesch'!C32="","",'Anita Klesch'!C32) | H33: =IF(Jeremy!B32="","",Jeremy!B32) | I33: =IF(Jeremy!D32="","",Jeremy!D32) | J33: =IF('Test Patient'!B32="","",'Test Patient'!B32) | K33: =IF('Test Patient'!D32="","",'Test Patient'!D32) | L33: =IF('Test Patient 2'!B32="","",'Test Patient 2'!B32) | M33: =IF('Test Patient 2'!C32="","",'Test Patient 2'!C32)
A34: ='Lucy Levene'!A33 -> 46239 | B34: =IF('Lucy Levene'!B33="","",'Lucy Levene'!B33) | C34: =IF('Lucy Levene'!D33="","",'Lucy Levene'!D33) | D34: =IF('Tom Bock'!B33="","",'Tom Bock'!B33) | E34: =IF('Tom Bock'!D33="","",'Tom Bock'!D33) | F34: =IF('Anita Klesch'!B33="","",'Anita Klesch'!B33) | G34: =IF('Anita Klesch'!C33="","",'Anita Klesch'!C33) | H34: =IF(Jeremy!B33="","",Jeremy!B33) | I34: =IF(Jeremy!D33="","",Jeremy!D33) | J34: =IF('Test Patient'!B33="","",'Test Patient'!B33) | K34: =IF('Test Patient'!D33="","",'Test Patient'!D33) | L34: =IF('Test Patient 2'!B33="","",'Test Patient 2'!B33) | M34: =IF('Test Patient 2'!C33="","",'Test Patient 2'!C33)
A35: ='Lucy Levene'!A34 -> 46240 | B35: =IF('Lucy Levene'!B34="","",'Lucy Levene'!B34) | C35: =IF('Lucy Levene'!D34="","",'Lucy Levene'!D34) | D35: =IF('Tom Bock'!B34="","",'Tom Bock'!B34) | E35: =IF('Tom Bock'!D34="","",'Tom Bock'!D34) | F35: =IF('Anita Klesch'!B34="","",'Anita Klesch'!B34) | G35: =IF('Anita Klesch'!C34="","",'Anita Klesch'!C34) | H35: =IF(Jeremy!B34="","",Jeremy!B34) | I35: =IF(Jeremy!D34="","",Jeremy!D34) | J35: =IF('Test Patient'!B34="","",'Test Patient'!B34) | K35: =IF('Test Patient'!D34="","",'Test Patient'!D34) | L35: =IF('Test Patient 2'!B34="","",'Test Patient 2'!B34) | M35: =IF('Test Patient 2'!C34="","",'Test Patient 2'!C34)
A36: ='Lucy Levene'!A35 -> 46241 | B36: =IF('Lucy Levene'!B35="","",'Lucy Levene'!B35) | C36: =IF('Lucy Levene'!D35="","",'Lucy Levene'!D35) | D36: =IF('Tom Bock'!B35="","",'Tom Bock'!B35) | E36: =IF('Tom Bock'!D35="","",'Tom Bock'!D35) | F36: =IF('Anita Klesch'!B35="","",'Anita Klesch'!B35) | G36: =IF('Anita Klesch'!C35="","",'Anita Klesch'!C35) | H36: =IF(Jeremy!B35="","",Jeremy!B35) | I36: =IF(Jeremy!D35="","",Jeremy!D35) | J36: =IF('Test Patient'!B35="","",'Test Patient'!B35) | K36: =IF('Test Patient'!D35="","",'Test Patient'!D35) | L36: =IF('Test Patient 2'!B35="","",'Test Patient 2'!B35) | M36: =IF('Test Patient 2'!C35="","",'Test Patient 2'!C35)
A37: ='Lucy Levene'!A36 -> 46242 | B37: =IF('Lucy Levene'!B36="","",'Lucy Levene'!B36) | C37: =IF('Lucy Levene'!D36="","",'Lucy Levene'!D36) | D37: =IF('Tom Bock'!B36="","",'Tom Bock'!B36) | E37: =IF('Tom Bock'!D36="","",'Tom Bock'!D36) | F37: =IF('Anita Klesch'!B36="","",'Anita Klesch'!B36) | G37: =IF('Anita Klesch'!C36="","",'Anita Klesch'!C36) | H37: =IF(Jeremy!B36="","",Jeremy!B36) | I37: =IF(Jeremy!D36="","",Jeremy!D36) | J37: =IF('Test Patient'!B36="","",'Test Patient'!B36) | K37: =IF('Test Patient'!D36="","",'Test Patient'!D36) | L37: =IF('Test Patient 2'!B36="","",'Test Patient 2'!B36) | M37: =IF('Test Patient 2'!C36="","",'Test Patient 2'!C36)
A38: ='Lucy Levene'!A37 -> 46243 | B38: =IF('Lucy Levene'!B37="","",'Lucy Levene'!B37) | C38: =IF('Lucy Levene'!D37="","",'Lucy Levene'!D37) | D38: =IF('Tom Bock'!B37="","",'Tom Bock'!B37) | E38: =IF('Tom Bock'!D37="","",'Tom Bock'!D37) | F38: =IF('Anita Klesch'!B37="","",'Anita Klesch'!B37) | G38: =IF('Anita Klesch'!C37="","",'Anita Klesch'!C37) | H38: =IF(Jeremy!B37="","",Jeremy!B37) | I38: =IF(Jeremy!D37="","",Jeremy!D37) | J38: =IF('Test Patient'!B37="","",'Test Patient'!B37) | K38: =IF('Test Patient'!D37="","",'Test Patient'!D37) | L38: =IF('Test Patient 2'!B37="","",'Test Patient 2'!B37) | M38: =IF('Test Patient 2'!C37="","",'Test Patient 2'!C37)
A39: ='Lucy Levene'!A38 -> 46244 | B39: =IF('Lucy Levene'!B38="","",'Lucy Levene'!B38) | C39: =IF('Lucy Levene'!D38="","",'Lucy Levene'!D38) | D39: =IF('Tom Bock'!B38="","",'Tom Bock'!B38) | E39: =IF('Tom Bock'!D38="","",'Tom Bock'!D38) | F39: =IF('Anita Klesch'!B38="","",'Anita Klesch'!B38) | G39: =IF('Anita Klesch'!C38="","",'Anita Klesch'!C38) | H39: =IF(Jeremy!B38="","",Jeremy!B38) | I39: =IF(Jeremy!D38="","",Jeremy!D38) | J39: =IF('Test Patient'!B38="","",'Test Patient'!B38) | K39: =IF('Test Patient'!D38="","",'Test Patient'!D38) | L39: =IF('Test Patient 2'!B38="","",'Test Patient 2'!B38) | M39: =IF('Test Patient 2'!C38="","",'Test Patient 2'!C38)
A40: ='Lucy Levene'!A39 -> 46245 | B40: =IF('Lucy Levene'!B39="","",'Lucy Levene'!B39) | C40: =IF('Lucy Levene'!D39="","",'Lucy Levene'!D39) | D40: =IF('Tom Bock'!B39="","",'Tom Bock'!B39) | E40: =IF('Tom Bock'!D39="","",'Tom Bock'!D39) | F40: =IF('Anita Klesch'!B39="","",'Anita Klesch'!B39) | G40: =IF('Anita Klesch'!C39="","",'Anita Klesch'!C39) | H40: =IF(Jeremy!B39="","",Jeremy!B39) | I40: =IF(Jeremy!D39="","",Jeremy!D39) | J40: =IF('Test Patient'!B39="","",'Test Patient'!B39) | K40: =IF('Test Patient'!D39="","",'Test Patient'!D39) | L40: =IF('Test Patient 2'!B39="","",'Test Patient 2'!B39) | M40: =IF('Test Patient 2'!C39="","",'Test Patient 2'!C39)
A41: ='Lucy Levene'!A40 -> 46246 | B41: =IF('Lucy Levene'!B40="","",'Lucy Levene'!B40) | C41: =IF('Lucy Levene'!D40="","",'Lucy Levene'!D40) | D41: =IF('Tom Bock'!B40="","",'Tom Bock'!B40) | E41: =IF('Tom Bock'!D40="","",'Tom Bock'!D40) | F41: =IF('Anita Klesch'!B40="","",'Anita Klesch'!B40) | G41: =IF('Anita Klesch'!C40="","",'Anita Klesch'!C40) | H41: =IF(Jeremy!B40="","",Jeremy!B40) | I41: =IF(Jeremy!D40="","",Jeremy!D40) | J41: =IF('Test Patient'!B40="","",'Test Patient'!B40) | K41: =IF('Test Patient'!D40="","",'Test Patient'!D40) | L41: =IF('Test Patient 2'!B40="","",'Test Patient 2'!B40) | M41: =IF('Test Patient 2'!C40="","",'Test Patient 2'!C40)
...

Sheet Dashboard
A1: Care Rota - Central Dashboard
A3: Shift Hours (editable) | D3: Staff Roster | F3: Client Engagement Dates
A4: Visit (AM / PM) | B4: 2 | D4: Billie | F4: Client | G4: Start | H4: End | K4: Time options
A5: Day Shift | B5: 12 | D5: Roderick | F5: Lucy Levene | G5: =DATE(2026,7,8) -> 46211 | K5: =TIME(6,0,0) -> 0.25
A6: Night Shift | B6: 12 | D6: Meseret | F6: Tom Bock | G6: =DATE(2026,7,17) -> 46220 | H6: =DATE(2026,7,19) -> 46222 | K6: =K5+TIME(0,30,0) -> 0.27083333
A7: Day starts | B7: =TIME(8,0,0) -> 0.33333333 | D7: Naresh | F7: Anita Klesch | G7: =DATE(2026,7,8) -> 46211 | H7: =DATE(2026,7,22) -> 46225 | K7: =K6+TIME(0,30,0) -> 0.29166667
A8: Day ends | B8: =TIME(20,0,0) -> 0.83333333 | D8: Rochelle | F8: Jeremy Thomas | G8: =DATE(2026,7,8) -> 46211 | H8: =DATE(2026,8,14) -> 46248 | K8: =K7+TIME(0,30,0) -> 0.3125
D9: Maica | F9: Test Patient | G9: =DATE(2026,7,8) -> 46211 | H9: =DATE(2026,8,14) -> 46248 | K9: =K8+TIME(0,30,0) -> 0.33333333
D10: Ricardo | F10: Test Patient 2 | G10: =DATE(2026,7,8) -> 46211 | H10: =DATE(2026,8,14) -> 46248 | K10: =K9+TIME(0,30,0) -> 0.35416667
A11: Staff Totals (whole rota) | D11: Veronica | E11: Client Activity | K11: =K10+TIME(0,30,0) -> 0.375
A12: Staff | B12: Shifts | C12: Hours | D12: Ruth | E12: Client | F12: Scheduled | G12: Coverage | H12: Gaps | K12: =K11+TIME(0,30,0) -> 0.39583333
A13: =IF(D4="","",D4) -> Billie | B13: =IF($A13="","",COUNTIF('Lucy Levene'!$M$5:$O$42,$A13)+COUNTIF('Tom Bock'!$M$5:$O$42,$A13)+COUNTIF(Jeremy!$M$5:$O$42,$A13)+COUNTIF('Test Patient'!$M$5:$O$42,$A13)+COUNTIF('Anita Klesch'!$M$5:$N$42,$A13)+COUNTIF('Test Patient 2'!$M$5:$N$42,$A13)) -> 12 | C13: =IF($A13="","",(COUNTIF('Lucy Levene'!$M$5:$O$42,$A13)+COUNTIF('Tom Bock'!$M$5:$O$42,$A13)+COUNTIF(Jeremy!$M$5:$O$42,$A13)+COUNTIF('Test Patient'!$M$5:$O$42,$A13))*VisitHrs+(COUNTIF('Anita Klesch'!$M$5:$M$42,$A13)+COUNTIF('Test Patient 2'!$M$5:$M$42,$A13))*DayHrs+(COUNTIF('Anita Klesch'!$N$5:$N$42,$A13)+COUNTIF('Test Patient 2'!$N$5:$N$42,$A13))*NightHrs) -> 24 | D13: Joriza | E13: Lucy Levene | F13: =SUM('Lucy Levene'!$I$5:$I$42) -> 47 | G13: — | H13: — | K13: =K12+TIME(0,30,0) -> 0.41666667
A14: =IF(D5="","",D5) -> Roderick | B14: =IF($A14="","",COUNTIF('Lucy Levene'!$M$5:$O$42,$A14)+COUNTIF('Tom Bock'!$M$5:$O$42,$A14)+COUNTIF(Jeremy!$M$5:$O$42,$A14)+COUNTIF('Test Patient'!$M$5:$O$42,$A14)+COUNTIF('Anita Klesch'!$M$5:$N$42,$A14)+COUNTIF('Test Patient 2'!$M$5:$N$42,$A14)) -> 25 | C14: =IF($A14="","",(COUNTIF('Lucy Levene'!$M$5:$O$42,$A14)+COUNTIF('Tom Bock'!$M$5:$O$42,$A14)+COUNTIF(Jeremy!$M$5:$O$42,$A14)+COUNTIF('Test Patient'!$M$5:$O$42,$A14))*VisitHrs+(COUNTIF('Anita Klesch'!$M$5:$M$42,$A14)+COUNTIF('Test Patient 2'!$M$5:$M$42,$A14))*DayHrs+(COUNTIF('Anita Klesch'!$N$5:$N$42,$A14)+COUNTIF('Test Patient 2'!$N$5:$N$42,$A14))*NightHrs) -> 50 | E14: Tom Bock | F14: =SUM('Tom Bock'!$I$5:$I$42) -> 0 | G14: — | H14: — | K14: =K13+TIME(0,30,0) -> 0.4375
A15: =IF(D6="","",D6) -> Meseret | B15: =IF($A15="","",COUNTIF('Lucy Levene'!$M$5:$O$42,$A15)+COUNTIF('Tom Bock'!$M$5:$O$42,$A15)+COUNTIF(Jeremy!$M$5:$O$42,$A15)+COUNTIF('Test Patient'!$M$5:$O$42,$A15)+COUNTIF('Anita Klesch'!$M$5:$N$42,$A15)+COUNTIF('Test Patient 2'!$M$5:$N$42,$A15)) -> 2 | C15: =IF($A15="","",(COUNTIF('Lucy Levene'!$M$5:$O$42,$A15)+COUNTIF('Tom Bock'!$M$5:$O$42,$A15)+COUNTIF(Jeremy!$M$5:$O$42,$A15)+COUNTIF('Test Patient'!$M$5:$O$42,$A15))*VisitHrs+(COUNTIF('Anita Klesch'!$M$5:$M$42,$A15)+COUNTIF('Test Patient 2'!$M$5:$M$42,$A15))*DayHrs+(COUNTIF('Anita Klesch'!$N$5:$N$42,$A15)+COUNTIF('Test Patient 2'!$N$5:$N$42,$A15))*NightHrs) -> 4 | E15: Anita Klesch | F15: =COUNTIF('Anita Klesch'!$M$5:$N$42,"?*") -> 26 | G15: =IF(SUM('Anita Klesch'!$H$5:$H$42)=0,0,F15/(SUM('Anita Klesch'!$H$5:$H$42)*2)) -> 0.86666667 | H15: =SUM('Anita Klesch'!$H$5:$H$42)*2-F15 -> 4 | K15: =K14+TIME(0,30,0) -> 0.45833333
A16: =IF(D7="","",D7) -> Naresh | B16: =IF($A16="","",COUNTIF('Lucy Levene'!$M$5:$O$42,$A16)+COUNTIF('Tom Bock'!$M$5:$O$42,$A16)+COUNTIF(Jeremy!$M$5:$O$42,$A16)+COUNTIF('Test Patient'!$M$5:$O$42,$A16)+COUNTIF('Anita Klesch'!$M$5:$N$42,$A16)+COUNTIF('Test Patient 2'!$M$5:$N$42,$A16)) -> 9 | C16: =IF($A16="","",(COUNTIF('Lucy Levene'!$M$5:$O$42,$A16)+COUNTIF('Tom Bock'!$M$5:$O$42,$A16)+COUNTIF(Jeremy!$M$5:$O$42,$A16)+COUNTIF('Test Patient'!$M$5:$O$42,$A16))*VisitHrs+(COUNTIF('Anita Klesch'!$M$5:$M$42,$A16)+COUNTIF('Test Patient 2'!$M$5:$M$42,$A16))*DayHrs+(COUNTIF('Anita Klesch'!$N$5:$N$42,$A16)+COUNTIF('Test Patient 2'!$N$5:$N$42,$A16))*NightHrs) -> 108 | E16: Jeremy | F16: =SUM(Jeremy!$I$5:$I$42) -> 0 | G16: — | H16: — | K16: =K15+TIME(0,30,0) -> 0.47916667
A17: =IF(D8="","",D8) -> Rochelle | B17: =IF($A17="","",COUNTIF('Lucy Levene'!$M$5:$O$42,$A17)+COUNTIF('Tom Bock'!$M$5:$O$42,$A17)+COUNTIF(Jeremy!$M$5:$O$42,$A17)+COUNTIF('Test Patient'!$M$5:$O$42,$A17)+COUNTIF('Anita Klesch'!$M$5:$N$42,$A17)+COUNTIF('Test Patient 2'!$M$5:$N$42,$A17)) -> 11 | C17: =IF($A17="","",(COUNTIF('Lucy Levene'!$M$5:$O$42,$A17)+COUNTIF('Tom Bock'!$M$5:$O$42,$A17)+COUNTIF(Jeremy!$M$5:$O$42,$A17)+COUNTIF('Test Patient'!$M$5:$O$42,$A17))*VisitHrs+(COUNTIF('Anita Klesch'!$M$5:$M$42,$A17)+COUNTIF('Test Patient 2'!$M$5:$M$42,$A17))*DayHrs+(COUNTIF('Anita Klesch'!$N$5:$N$42,$A17)+COUNTIF('Test Patient 2'!$N$5:$N$42,$A17))*NightHrs) -> 52 | E17: Test Patient | F17: =SUM('Test Patient'!$I$5:$I$42) -> 0 | G17: — | H17: — | K17: =K16+TIME(0,30,0) -> 0.5
A18: =IF(D9="","",D9) -> Maica | B18: =IF($A18="","",COUNTIF('Lucy Levene'!$M$5:$O$42,$A18)+COUNTIF('Tom Bock'!$M$5:$O$42,$A18)+COUNTIF(Jeremy!$M$5:$O$42,$A18)+COUNTIF('Test Patient'!$M$5:$O$42,$A18)+COUNTIF('Anita Klesch'!$M$5:$N$42,$A18)+COUNTIF('Test Patient 2'!$M$5:$N$42,$A18)) -> 8 | C18: =IF($A18="","",(COUNTIF('Lucy Levene'!$M$5:$O$42,$A18)+COUNTIF('Tom Bock'!$M$5:$O$42,$A18)+COUNTIF(Jeremy!$M$5:$O$42,$A18)+COUNTIF('Test Patient'!$M$5:$O$42,$A18))*VisitHrs+(COUNTIF('Anita Klesch'!$M$5:$M$42,$A18)+COUNTIF('Test Patient 2'!$M$5:$M$42,$A18))*DayHrs+(COUNTIF('Anita Klesch'!$N$5:$N$42,$A18)+COUNTIF('Test Patient 2'!$N$5:$N$42,$A18))*NightHrs) -> 96 | E18: Test Patient 2 | F18: =COUNTIF('Test Patient 2'!$M$5:$N$42,"?*") -> 0 | G18: =IF(SUM('Test Patient 2'!$H$5:$H$42)=0,0,F18/(SUM('Test Patient 2'!$H$5:$H$42)*2)) -> 0 | H18: =SUM('Test Patient 2'!$H$5:$H$42)*2-F18 -> 76 | K18: =K17+TIME(0,30,0) -> 0.52083333
A19: =IF(D10="","",D10) -> Ricardo | B19: =IF($A19="","",COUNTIF('Lucy Levene'!$M$5:$O$42,$A19)+COUNTIF('Tom Bock'!$M$5:$O$42,$A19)+COUNTIF(Jeremy!$M$5:$O$42,$A19)+COUNTIF('Test Patient'!$M$5:$O$42,$A19)+COUNTIF('Anita Klesch'!$M$5:$N$42,$A19)+COUNTIF('Test Patient 2'!$M$5:$N$42,$A19)) -> 0 | C19: =IF($A19="","",(COUNTIF('Lucy Levene'!$M$5:$O$42,$A19)+COUNTIF('Tom Bock'!$M$5:$O$42,$A19)+COUNTIF(Jeremy!$M$5:$O$42,$A19)+COUNTIF('Test Patient'!$M$5:$O$42,$A19))*VisitHrs+(COUNTIF('Anita Klesch'!$M$5:$M$42,$A19)+COUNTIF('Test Patient 2'!$M$5:$M$42,$A19))*DayHrs+(COUNTIF('Anita Klesch'!$N$5:$N$42,$A19)+COUNTIF('Test Patient 2'!$N$5:$N$42,$A19))*NightHrs) -> 0 | K19: =K18+TIME(0,30,0) -> 0.54166667
A20: =IF(D11="","",D11) -> Veronica | B20: =IF($A20="","",COUNTIF('Lucy Levene'!$M$5:$O$42,$A20)+COUNTIF('Tom Bock'!$M$5:$O$42,$A20)+COUNTIF(Jeremy!$M$5:$O$42,$A20)+COUNTIF('Test Patient'!$M$5:$O$42,$A20)+COUNTIF('Anita Klesch'!$M$5:$N$42,$A20)+COUNTIF('Test Patient 2'!$M$5:$N$42,$A20)) -> 2 | C20: =IF($A20="","",(COUNTIF('Lucy Levene'!$M$5:$O$42,$A20)+COUNTIF('Tom Bock'!$M$5:$O$42,$A20)+COUNTIF(Jeremy!$M$5:$O$42,$A20)+COUNTIF('Test Patient'!$M$5:$O$42,$A20))*VisitHrs+(COUNTIF('Anita Klesch'!$M$5:$M$42,$A20)+COUNTIF('Test Patient 2'!$M$5:$M$42,$A20))*DayHrs+(COUNTIF('Anita Klesch'!$N$5:$N$42,$A20)+COUNTIF('Test Patient 2'!$N$5:$N$42,$A20))*NightHrs) -> 24 | E20: Double-Booking Alerts | K20: =K19+TIME(0,30,0) -> 0.5625
A21: =IF(D12="","",D12) -> Ruth | B21: =IF($A21="","",COUNTIF('Lucy Levene'!$M$5:$O$42,$A21)+COUNTIF('Tom Bock'!$M$5:$O$42,$A21)+COUNTIF(Jeremy!$M$5:$O$42,$A21)+COUNTIF('Test Patient'!$M$5:$O$42,$A21)+COUNTIF('Anita Klesch'!$M$5:$N$42,$A21)+COUNTIF('Test Patient 2'!$M$5:$N$42,$A21)) -> 3 | C21: =IF($A21="","",(COUNTIF('Lucy Levene'!$M$5:$O$42,$A21)+COUNTIF('Tom Bock'!$M$5:$O$42,$A21)+COUNTIF(Jeremy!$M$5:$O$42,$A21)+COUNTIF('Test Patient'!$M$5:$O$42,$A21))*VisitHrs+(COUNTIF('Anita Klesch'!$M$5:$M$42,$A21)+COUNTIF('Test Patient 2'!$M$5:$M$42,$A21))*DayHrs+(COUNTIF('Anita Klesch'!$N$5:$N$42,$A21)+COUNTIF('Test Patient 2'!$N$5:$N$42,$A21))*NightHrs) -> 36 | E21: Conflicting shift cells: | H21: =SUM('Lucy Levene'!$J$5:$L$42)+SUM('Tom Bock'!$J$5:$L$42)+SUM(Jeremy!$J$5:$L$42)+SUM('Test Patient'!$J$5:$L$42)+SUM('Anita Klesch'!$J$5:$K$42)+SUM('Test Patient 2'!$J$5:$K$42) -> 0 | K21: =K20+TIME(0,30,0) -> 0.58333333
A22: =IF(D13="","",D13) -> Joriza | B22: =IF($A22="","",COUNTIF('Lucy Levene'!$M$5:$O$42,$A22)+COUNTIF('Tom Bock'!$M$5:$O$42,$A22)+COUNTIF(Jeremy!$M$5:$O$42,$A22)+COUNTIF('Test Patient'!$M$5:$O$42,$A22)+COUNTIF('Anita Klesch'!$M$5:$N$42,$A22)+COUNTIF('Test Patient 2'!$M$5:$N$42,$A22)) -> 1 | C22: =IF($A22="","",(COUNTIF('Lucy Levene'!$M$5:$O$42,$A22)+COUNTIF('Tom Bock'!$M$5:$O$42,$A22)+COUNTIF(Jeremy!$M$5:$O$42,$A22)+COUNTIF('Test Patient'!$M$5:$O$42,$A22))*VisitHrs+(COUNTIF('Anita Klesch'!$M$5:$M$42,$A22)+COUNTIF('Test Patient 2'!$M$5:$M$42,$A22))*DayHrs+(COUNTIF('Anita Klesch'!$N$5:$N$42,$A22)+COUNTIF('Test Patient 2'!$N$5:$N$42,$A22))*NightHrs) -> 12 | E22: Flags same staff double-booked in overlapping time. Enter visit times to activate. | K22: =K21+TIME(0,30,0) -> 0.60416667
K23: =K22+TIME(0,30,0) -> 0.625
K24: =K23+TIME(0,30,0) -> 0.64583333
A25: Weekly Summary | K25: =K24+TIME(0,30,0) -> 0.66666667
A26: Week starting | B26: Filled | C26: Hours | D26: Gaps (Anita) | K26: =K25+TIME(0,30,0) -> 0.6875
A27: ='Lucy Levene'!A5 -> 46211 | B27: =SUM('Lucy Levene'!I5:I11)+SUM('Tom Bock'!I5:I11)+SUM(Jeremy!I5:I11)+SUM('Test Patient'!I5:I11)+COUNTIF('Anita Klesch'!M5:N11,"?*")+COUNTIF('Test Patient 2'!M5:N11,"?*") -> 25 | C27: =(SUM('Lucy Levene'!I5:I11)+SUM('Tom Bock'!I5:I11)+SUM(Jeremy!I5:I11)+SUM('Test Patient'!I5:I11))*VisitHrs+(COUNTIF('Anita Klesch'!M5:M11,"?*")+COUNTIF('Test Patient 2'!M5:M11,"?*"))*DayHrs+(COUNTIF('Anita Klesch'!N5:N11,"?*")+COUNTIF('Test Patient 2'!N5:N11,"?*"))*NightHrs -> 190 | D27: =(SUM('Anita Klesch'!H5:H11)+SUM('Test Patient 2'!H5:H11))*2-(COUNTIF('Anita Klesch'!M5:N11,"?*")+COUNTIF('Test Patient 2'!M5:N11,"?*")) -> 14 | K27: =K26+TIME(0,30,0) -> 0.70833333
A28: ='Lucy Levene'!A12 -> 46218 | B28: =SUM('Lucy Levene'!I12:I18)+SUM('Tom Bock'!I12:I18)+SUM(Jeremy!I12:I18)+SUM('Test Patient'!I12:I18)+COUNTIF('Anita Klesch'!M12:N18,"?*")+COUNTIF('Test Patient 2'!M12:N18,"?*") -> 26 | C28: =(SUM('Lucy Levene'!I12:I18)+SUM('Tom Bock'!I12:I18)+SUM(Jeremy!I12:I18)+SUM('Test Patient'!I12:I18))*VisitHrs+(COUNTIF('Anita Klesch'!M12:M18,"?*")+COUNTIF('Test Patient 2'!M12:M18,"?*"))*DayHrs+(COUNTIF('Anita Klesch'!N12:N18,"?*")+COUNTIF('Test Patient 2'!N12:N18,"?*"))*NightHrs -> 172 | D28: =(SUM('Anita Klesch'!H12:H18)+SUM('Test Patient 2'!H12:H18))*2-(COUNTIF('Anita Klesch'!M12:N18,"?*")+COUNTIF('Test Patient 2'!M12:N18,"?*")) -> 16 | K28: =K27+TIME(0,30,0) -> 0.72916667
A29: ='Lucy Levene'!A19 -> 46225 | B29: =SUM('Lucy Levene'!I19:I25)+SUM('Tom Bock'!I19:I25)+SUM(Jeremy!I19:I25)+SUM('Test Patient'!I19:I25)+COUNTIF('Anita Klesch'!M19:N25,"?*")+COUNTIF('Test Patient 2'!M19:N25,"?*") -> 14 | C29: =(SUM('Lucy Levene'!I19:I25)+SUM('Tom Bock'!I19:I25)+SUM(Jeremy!I19:I25)+SUM('Test Patient'!I19:I25))*VisitHrs+(COUNTIF('Anita Klesch'!M19:M25,"?*")+COUNTIF('Test Patient 2'!M19:M25,"?*"))*DayHrs+(COUNTIF('Anita Klesch'!N19:N25,"?*")+COUNTIF('Test Patient 2'!N19:N25,"?*"))*NightHrs -> 28 | D29: =(SUM('Anita Klesch'!H19:H25)+SUM('Test Patient 2'!H19:H25))*2-(COUNTIF('Anita Klesch'!M19:N25,"?*")+COUNTIF('Test Patient 2'!M19:N25,"?*")) -> 16 | K29: =K28+TIME(0,30,0) -> 0.75
A30: ='Lucy Levene'!A26 -> 46232 | B30: =SUM('Lucy Levene'!I26:I32)+SUM('Tom Bock'!I26:I32)+SUM(Jeremy!I26:I32)+SUM('Test Patient'!I26:I32)+COUNTIF('Anita Klesch'!M26:N32,"?*")+COUNTIF('Test Patient 2'!M26:N32,"?*") -> 8 | C30: =(SUM('Lucy Levene'!I26:I32)+SUM('Tom Bock'!I26:I32)+SUM(Jeremy!I26:I32)+SUM('Test Patient'!I26:I32))*VisitHrs+(COUNTIF('Anita Klesch'!M26:M32,"?*")+COUNTIF('Test Patient 2'!M26:M32,"?*"))*DayHrs+(COUNTIF('Anita Klesch'!N26:N32,"?*")+COUNTIF('Test Patient 2'!N26:N32,"?*"))*NightHrs -> 16 | D30: =(SUM('Anita Klesch'!H26:H32)+SUM('Test Patient 2'!H26:H32))*2-(COUNTIF('Anita Klesch'!M26:N32,"?*")+COUNTIF('Test Patient 2'!M26:N32,"?*")) -> 14 | K30: =K29+TIME(0,30,0) -> 0.77083333
A31: ='Lucy Levene'!A33 -> 46239 | B31: =SUM('Lucy Levene'!I33:I39)+SUM('Tom Bock'!I33:I39)+SUM(Jeremy!I33:I39)+SUM('Test Patient'!I33:I39)+COUNTIF('Anita Klesch'!M33:N39,"?*")+COUNTIF('Test Patient 2'!M33:N39,"?*") -> 0 | C31: =(SUM('Lucy Levene'!I33:I39)+SUM('Tom Bock'!I33:I39)+SUM(Jeremy!I33:I39)+SUM('Test Patient'!I33:I39))*VisitHrs+(COUNTIF('Anita Klesch'!M33:M39,"?*")+COUNTIF('Test Patient 2'!M33:M39,"?*"))*DayHrs+(COUNTIF('Anita Klesch'!N33:N39,"?*")+COUNTIF('Test Patient 2'!N33:N39,"?*"))*NightHrs -> 0 | D31: =(SUM('Anita Klesch'!H33:H39)+SUM('Test Patient 2'!H33:H39))*2-(COUNTIF('Anita Klesch'!M33:N39,"?*")+COUNTIF('Test Patient 2'!M33:N39,"?*")) -> 14 | K31: =K30+TIME(0,30,0) -> 0.79166667
A32: ='Lucy Levene'!A40 -> 46246 | B32: =SUM('Lucy Levene'!I40:I42)+SUM('Tom Bock'!I40:I42)+SUM(Jeremy!I40:I42)+SUM('Test Patient'!I40:I42)+COUNTIF('Anita Klesch'!M40:N42,"?*")+COUNTIF('Test Patient 2'!M40:N42,"?*") -> 0 | C32: =(SUM('Lucy Levene'!I40:I42)+SUM('Tom Bock'!I40:I42)+SUM(Jeremy!I40:I42)+SUM('Test Patient'!I40:I42))*VisitHrs+(COUNTIF('Anita Klesch'!M40:M42,"?*")+COUNTIF('Test Patient 2'!M40:M42,"?*"))*DayHrs+(COUNTIF('Anita Klesch'!N40:N42,"?*")+COUNTIF('Test Patient 2'!N40:N42,"?*"))*NightHrs -> 0 | D32: =(SUM('Anita Klesch'!H40:H42)+SUM('Test Patient 2'!H40:H42))*2-(COUNTIF('Anita Klesch'!M40:N42,"?*")+COUNTIF('Test Patient 2'!M40:N42,"?*")) -> 6 | K32: =K31+TIME(0,30,0) -> 0.8125
A33: TOTAL | B33: =SUM(B27:B32) -> 73 | C33: =SUM(C27:C32) -> 406 | D33: =SUM(D27:D32) -> 80 | K33: =K32+TIME(0,30,0) -> 0.83333333
K34: =K33+TIME(0,30,0) -> 0.85416667
K35: =K34+TIME(0,30,0) -> 0.875
K36: =K35+TIME(0,30,0) -> 0.89583333
K37: =K36+TIME(0,30,0) -> 0.91666667

Sheet Lucy Levene
A1: Lucy Levene — Care Rota
A2: Visits · AM & PM (2 hours each)
A4: Date | B4: Visit 1 | C4: Time | D4: Visit 2 | E4: Time | F4: Visit 3 | G4: Time | H4: inWin | I4: visits | J4: fV1 | K4: fV2 | L4: fV3 | M4: effV1 | N4: effV2 | O4: effV3
A5: =DATE(2026,7,8) -> 46211 | H5: =IF($A5="",0,IF(AND(OR(NOT(ISNUMBER(LL_Start)),LL_Start=0,$A5>=LL_Start),OR(NOT(ISNUMBER(LL_End)),LL_End=0,$A5<=LL_End)),1,0)) -> 1 | I5: =IF($H5=1,($B5<>"")+($D5<>"")+($F5<>""),0) -> 0 | J5: =IF(AND($H5=1,$B5<>"",ISNUMBER($C5)),IF(((('Lucy Levene'!B5=$B5)*ISNUMBER('Lucy Levene'!C5)*(ABS('Lucy Levene'!C5-$C5)<VisitHrs/24)+('Lucy Levene'!D5=$B5)*ISNUMBER('Lucy Levene'!E5)*(ABS('Lucy Levene'!E5-$C5)<VisitHrs/24)+('Lucy Levene'!F5=$B5)*ISNUMBER('Lucy Levene'!G5)*(ABS('Lucy Levene'!G5-$C5)<VisitHrs/24)+('Tom Bock'!B5=$B5)*ISNUMBER('Tom Bock'!C5)*(ABS('Tom Bock'!C5-$C5)<VisitHrs/24)+('Tom Bock'!D5=$B5)*ISNUMBER('Tom Bock'!E5)*(ABS('Tom Bock'!E5-$C5)<VisitHrs/24)+('Tom Bock'!F5=$B5)*ISNUMBER('Tom Bock'!G5)*(ABS('Tom Bock'!G5-$C5)<VisitHrs/24)+(Jeremy!B5=$B5)*ISNUMBER(Jeremy!C5)*(ABS(Jeremy!C5-$C5)<VisitHrs/24)+(Jeremy!D5=$B5)*ISNUMBER(Jeremy!E5)*(ABS(Jeremy!E5-$C5)<VisitHrs/24)+(Jeremy!F5=$B5)*ISNUMBER(Jeremy!G5)*(ABS(Jeremy!G5-$C5)<VisitHrs/24)+('Test Patient'!B5=$B5)*ISNUMBER('Test Patient'!C5)*(ABS('Test Patient'!C5-$C5)<VisitHrs/24)+('Test Patient'!D5=$B5)*ISNUMBER('Test Patient'!E5)*(ABS('Test Patient'!E5-$C5)<VisitHrs/24)+('Test Patient'!F5=$B5)*ISNUMBER('Test Patient'!G5)*(ABS('Test Patient'!G5-$C5)<VisitHrs/24))-1)+('Anita Klesch'!$B5=$B5)*($C5<DayEnd)*($C5+VisitHrs/24>DayStart)+('Anita Klesch'!$C5=$B5)*((($C5+VisitHrs/24>DayEnd)+($C5<DayStart))>0)+('Test Patient 2'!$B5=$B5)*($C5<DayEnd)*($C5+VisitHrs/24>DayStart)+('Test Patient 2'!$C5=$B5)*((($C5+VisitHrs/24>DayEnd)+($C5<DayStart))>0)>=1,1,0),0) -> 0 | K5: =IF(AND($H5=1,$D5<>"",ISNUMBER($E5)),IF(((('Lucy Levene'!B5=$D5)*ISNUMBER('Lucy Levene'!C5)*(ABS('Lucy Levene'!C5-$E5)<VisitHrs/24)+('Lucy Levene'!D5=$D5)*ISNUMBER('Lucy Levene'!E5)*(ABS('Lucy Levene'!E5-$E5)<VisitHrs/24)+('Lucy Levene'!F5=$D5)*ISNUMBER('Lucy Levene'!G5)*(ABS('Lucy Levene'!G5-$E5)<VisitHrs/24)+('Tom Bock'!B5=$D5)*ISNUMBER('Tom Bock'!C5)*(ABS('Tom Bock'!C5-$E5)<VisitHrs/24)+('Tom Bock'!D5=$D5)*ISNUMBER('Tom Bock'!E5)*(ABS('Tom Bock'!E5-$E5)<VisitHrs/24)+('Tom Bock'!F5=$D5)*ISNUMBER('Tom Bock'!G5)*(ABS('Tom Bock'!G5-$E5)<VisitHrs/24)+(Jeremy!B5=$D5)*ISNUMBER(Jeremy!C5)*(ABS(Jeremy!C5-$E5)<VisitHrs/24)+(Jeremy!D5=$D5)*ISNUMBER(Jeremy!E5)*(ABS(Jeremy!E5-$E5)<VisitHrs/24)+(Jeremy!F5=$D5)*ISNUMBER(Jeremy!G5)*(ABS(Jeremy!G5-$E5)<VisitHrs/24)+('Test Patient'!B5=$D5)*ISNUMBER('Test Patient'!C5)*(ABS('Test Patient'!C5-$E5)<VisitHrs/24)+('Test Patient'!D5=$D5)*ISNUMBER('Test Patient'!E5)*(ABS('Test Patient'!E5-$E5)<VisitHrs/24)+('Test Patient'!F5=$D5)*ISNUMBER('Test Patient'!G5)*(ABS('Test Patient'!G5-$E5)<VisitHrs/24))-1)+('Anita Klesch'!$B5=$D5)*($E5<DayEnd)*($E5+VisitHrs/24>DayStart)+('Anita Klesch'!$C5=$D5)*((($E5+VisitHrs/24>DayEnd)+($E5<DayStart))>0)+('Test Patient 2'!$B5=$D5)*($E5<DayEnd)*($E5+VisitHrs/24>DayStart)+('Test Patient 2'!$C5=$D5)*((($E5+VisitHrs/24>DayEnd)+($E5<DayStart))>0)>=1,1,0),0) -> 0 | L5: =IF(AND($H5=1,$F5<>"",ISNUMBER($G5)),IF(((('Lucy Levene'!B5=$F5)*ISNUMBER('Lucy Levene'!C5)*(ABS('Lucy Levene'!C5-$G5)<VisitHrs/24)+('Lucy Levene'!D5=$F5)*ISNUMBER('Lucy Levene'!E5)*(ABS('Lucy Levene'!E5-$G5)<VisitHrs/24)+('Lucy Levene'!F5=$F5)*ISNUMBER('Lucy Levene'!G5)*(ABS('Lucy Levene'!G5-$G5)<VisitHrs/24)+('Tom Bock'!B5=$F5)*ISNUMBER('Tom Bock'!C5)*(ABS('Tom Bock'!C5-$G5)<VisitHrs/24)+('Tom Bock'!D5=$F5)*ISNUMBER('Tom Bock'!E5)*(ABS('Tom Bock'!E5-$G5)<VisitHrs/24)+('Tom Bock'!F5=$F5)*ISNUMBER('Tom Bock'!G5)*(ABS('Tom Bock'!G5-$G5)<VisitHrs/24)+(Jeremy!B5=$F5)*ISNUMBER(Jeremy!C5)*(ABS(Jeremy!C5-$G5)<VisitHrs/24)+(Jeremy!D5=$F5)*ISNUMBER(Jeremy!E5)*(ABS(Jeremy!E5-$G5)<VisitHrs/24)+(Jeremy!F5=$F5)*ISNUMBER(Jeremy!G5)*(ABS(Jeremy!G5-$G5)<VisitHrs/24)+('Test Patient'!B5=$F5)*ISNUMBER('Test Patient'!C5)*(ABS('Test Patient'!C5-$G5)<VisitHrs/24)+('Test Patient'!D5=$F5)*ISNUMBER('Test Patient'!E5)*(ABS('Test Patient'!E5-$G5)<VisitHrs/24)+('Test Patient'!F5=$F5)*ISNUMBER('Test Patient'!G5)*(ABS('Test Patient'!G5-$G5)<VisitHrs/24))-1)+('Anita Klesch'!$B5=$F5)*($G5<DayEnd)*($G5+VisitHrs/24>DayStart)+('Anita Klesch'!$C5=$F5)*((($G5+VisitHrs/24>DayEnd)+($G5<DayStart))>0)+('Test Patient 2'!$B5=$F5)*($G5<DayEnd)*($G5+VisitHrs/24>DayStart)+('Test Patient 2'!$C5=$F5)*((($G5+VisitHrs/24>DayEnd)+($G5<DayStart))>0)>=1,1,0),0) -> 0 | M5: =IF($H5=1,$B5,"") -> 0 | N5: =IF($H5=1,$D5,"") -> 0 | O5: =IF($H5=1,$F5,"") -> 0
A6: =A5+1 -> 46212 | D6: Roderick | E6: 0.85416667 | H6: =IF($A6="",0,IF(AND(OR(NOT(ISNUMBER(LL_Start)),LL_Start=0,$A6>=LL_Start),OR(NOT(ISNUMBER(LL_End)),LL_End=0,$A6<=LL_End)),1,0)) -> 1 | I6: =IF($H6=1,($B6<>"")+($D6<>"")+($F6<>""),0) -> 1 | J6: =IF(AND($H6=1,$B6<>"",ISNUMBER($C6)),IF(((('Lucy Levene'!B6=$B6)*ISNUMBER('Lucy Levene'!C6)*(ABS('Lucy Levene'!C6-$C6)<VisitHrs/24)+('Lucy Levene'!D6=$B6)*ISNUMBER('Lucy Levene'!E6)*(ABS('Lucy Levene'!E6-$C6)<VisitHrs/24)+('Lucy Levene'!F6=$B6)*ISNUMBER('Lucy Levene'!G6)*(ABS('Lucy Levene'!G6-$C6)<VisitHrs/24)+('Tom Bock'!B6=$B6)*ISNUMBER('Tom Bock'!C6)*(ABS('Tom Bock'!C6-$C6)<VisitHrs/24)+('Tom Bock'!D6=$B6)*ISNUMBER('Tom Bock'!E6)*(ABS('Tom Bock'!E6-$C6)<VisitHrs/24)+('Tom Bock'!F6=$B6)*ISNUMBER('Tom Bock'!G6)*(ABS('Tom Bock'!G6-$C6)<VisitHrs/24)+(Jeremy!B6=$B6)*ISNUMBER(Jeremy!C6)*(ABS(Jeremy!C6-$C6)<VisitHrs/24)+(Jeremy!D6=$B6)*ISNUMBER(Jeremy!E6)*(ABS(Jeremy!E6-$C6)<VisitHrs/24)+(Jeremy!F6=$B6)*ISNUMBER(Jeremy!G6)*(ABS(Jeremy!G6-$C6)<VisitHrs/24)+('Test Patient'!B6=$B6)*ISNUMBER('Test Patient'!C6)*(ABS('Test Patient'!C6-$C6)<VisitHrs/24)+('Test Patient'!D6=$B6)*ISNUMBER('Test Patient'!E6)*(ABS('Test Patient'!E6-$C6)<VisitHrs/24)+('Test Patient'!F6=$B6)*ISNUMBER('Test Patient'!G6)*(ABS('Test Patient'!G6-$C6)<VisitHrs/24))-1)+('Anita Klesch'!$B6=$B6)*($C6<DayEnd)*($C6+VisitHrs/24>DayStart)+('Anita Klesch'!$C6=$B6)*((($C6+VisitHrs/24>DayEnd)+($C6<DayStart))>0)+('Test Patient 2'!$B6=$B6)*($C6<DayEnd)*($C6+VisitHrs/24>DayStart)+('Test Patient 2'!$C6=$B6)*((($C6+VisitHrs/24>DayEnd)+($C6<DayStart))>0)>=1,1,0),0) -> 0 | K6: =IF(AND($H6=1,$D6<>"",ISNUMBER($E6)),IF(((('Lucy Levene'!B6=$D6)*ISNUMBER('Lucy Levene'!C6)*(ABS('Lucy Levene'!C6-$E6)<VisitHrs/24)+('Lucy Levene'!D6=$D6)*ISNUMBER('Lucy Levene'!E6)*(ABS('Lucy Levene'!E6-$E6)<VisitHrs/24)+('Lucy Levene'!F6=$D6)*ISNUMBER('Lucy Levene'!G6)*(ABS('Lucy Levene'!G6-$E6)<VisitHrs/24)+('Tom Bock'!B6=$D6)*ISNUMBER('Tom Bock'!C6)*(ABS('Tom Bock'!C6-$E6)<VisitHrs/24)+('Tom Bock'!D6=$D6)*ISNUMBER('Tom Bock'!E6)*(ABS('Tom Bock'!E6-$E6)<VisitHrs/24)+('Tom Bock'!F6=$D6)*ISNUMBER('Tom Bock'!G6)*(ABS('Tom Bock'!G6-$E6)<VisitHrs/24)+(Jeremy!B6=$D6)*ISNUMBER(Jeremy!C6)*(ABS(Jeremy!C6-$E6)<VisitHrs/24)+(Jeremy!D6=$D6)*ISNUMBER(Jeremy!E6)*(ABS(Jeremy!E6-$E6)<VisitHrs/24)+(Jeremy!F6=$D6)*ISNUMBER(Jeremy!G6)*(ABS(Jeremy!G6-$E6)<VisitHrs/24)+('Test Patient'!B6=$D6)*ISNUMBER('Test Patient'!C6)*(ABS('Test Patient'!C6-$E6)<VisitHrs/24)+('Test Patient'!D6=$D6)*ISNUMBER('Test Patient'!E6)*(ABS('Test Patient'!E6-$E6)<VisitHrs/24)+('Test Patient'!F6=$D6)*ISNUMBER('Test Patient'!G6)*(ABS('Test Patient'!G6-$E6)<VisitHrs/24))-1)+('Anita Klesch'!$B6=$D6)*($E6<DayEnd)*($E6+VisitHrs/24>DayStart)+('Anita Klesch'!$C6=$D6)*((($E6+VisitHrs/24>DayEnd)+($E6<DayStart))>0)+('Test Patient 2'!$B6=$D6)*($E6<DayEnd)*($E6+VisitHrs/24>DayStart)+('Test Patient 2'!$C6=$D6)*((($E6+VisitHrs/24>DayEnd)+($E6<DayStart))>0)>=1,1,0),0) -> 0 | L6: =IF(AND($H6=1,$F6<>"",ISNUMBER($G6)),IF(((('Lucy Levene'!B6=$F6)*ISNUMBER('Lucy Levene'!C6)*(ABS('Lucy Levene'!C6-$G6)<VisitHrs/24)+('Lucy Levene'!D6=$F6)*ISNUMBER('Lucy Levene'!E6)*(ABS('Lucy Levene'!E6-$G6)<VisitHrs/24)+('Lucy Levene'!F6=$F6)*ISNUMBER('Lucy Levene'!G6)*(ABS('Lucy Levene'!G6-$G6)<VisitHrs/24)+('Tom Bock'!B6=$F6)*ISNUMBER('Tom Bock'!C6)*(ABS('Tom Bock'!C6-$G6)<VisitHrs/24)+('Tom Bock'!D6=$F6)*ISNUMBER('Tom Bock'!E6)*(ABS('Tom Bock'!E6-$G6)<VisitHrs/24)+('Tom Bock'!F6=$F6)*ISNUMBER('Tom Bock'!G6)*(ABS('Tom Bock'!G6-$G6)<VisitHrs/24)+(Jeremy!B6=$F6)*ISNUMBER(Jeremy!C6)*(ABS(Jeremy!C6-$G6)<VisitHrs/24)+(Jeremy!D6=$F6)*ISNUMBER(Jeremy!E6)*(ABS(Jeremy!E6-$G6)<VisitHrs/24)+(Jeremy!F6=$F6)*ISNUMBER(Jeremy!G6)*(ABS(Jeremy!G6-$G6)<VisitHrs/24)+('Test Patient'!B6=$F6)*ISNUMBER('Test Patient'!C6)*(ABS('Test Patient'!C6-$G6)<VisitHrs/24)+('Test Patient'!D6=$F6)*ISNUMBER('Test Patient'!E6)*(ABS('Test Patient'!E6-$G6)<VisitHrs/24)+('Test Patient'!F6=$F6)*ISNUMBER('Test Patient'!G6)*(ABS('Test Patient'!G6-$G6)<VisitHrs/24))-1)+('Anita Klesch'!$B6=$F6)*($G6<DayEnd)*($G6+VisitHrs/24>DayStart)+('Anita Klesch'!$C6=$F6)*((($G6+VisitHrs/24>DayEnd)+($G6<DayStart))>0)+('Test Patient 2'!$B6=$F6)*($G6<DayEnd)*($G6+VisitHrs/24>DayStart)+('Test Patient 2'!$C6=$F6)*((($G6+VisitHrs/24>DayEnd)+($G6<DayStart))>0)>=1,1,0),0) -> 0 | M6: =IF($H6=1,$B6,"") -> 0 | N6: =IF($H6=1,$D6,"") -> Roderick | O6: =IF($H6=1,$F6,"") -> 0
A7: =A6+1 -> 46213 | B7: Billie | C7: 0.35416667 | D7: Billie | H7: =IF($A7="",0,IF(AND(OR(NOT(ISNUMBER(LL_Start)),LL_Start=0,$A7>=LL_Start),OR(NOT(ISNUMBER(LL_End)),LL_End=0,$A7<=LL_End)),1,0)) -> 1 | I7: =IF($H7=1,($B7<>"")+($D7<>"")+($F7<>""),0) -> 2 | J7: =IF(AND($H7=1,$B7<>"",ISNUMBER($C7)),IF(((('Lucy Levene'!B7=$B7)*ISNUMBER('Lucy Levene'!C7)*(ABS('Lucy Levene'!C7-$C7)<VisitHrs/24)+('Lucy Levene'!D7=$B7)*ISNUMBER('Lucy Levene'!E7)*(ABS('Lucy Levene'!E7-$C7)<VisitHrs/24)+('Lucy Levene'!F7=$B7)*ISNUMBER('Lucy Levene'!G7)*(ABS('Lucy Levene'!G7-$C7)<VisitHrs/24)+('Tom Bock'!B7=$B7)*ISNUMBER('Tom Bock'!C7)*(ABS('Tom Bock'!C7-$C7)<VisitHrs/24)+('Tom Bock'!D7=$B7)*ISNUMBER('Tom Bock'!E7)*(ABS('Tom Bock'!E7-$C7)<VisitHrs/24)+('Tom Bock'!F7=$B7)*ISNUMBER('Tom Bock'!G7)*(ABS('Tom Bock'!G7-$C7)<VisitHrs/24)+(Jeremy!B7=$B7)*ISNUMBER(Jeremy!C7)*(ABS(Jeremy!C7-$C7)<VisitHrs/24)+(Jeremy!D7=$B7)*ISNUMBER(Jeremy!E7)*(ABS(Jeremy!E7-$C7)<VisitHrs/24)+(Jeremy!F7=$B7)*ISNUMBER(Jeremy!G7)*(ABS(Jeremy!G7-$C7)<VisitHrs/24)+('Test Patient'!B7=$B7)*ISNUMBER('Test Patient'!C7)*(ABS('Test Patient'!C7-$C7)<VisitHrs/24)+('Test Patient'!D7=$B7)*ISNUMBER('Test Patient'!E7)*(ABS('Test Patient'!E7-$C7)<VisitHrs/24)+('Test Patient'!F7=$B7)*ISNUMBER('Test Patient'!G7)*(ABS('Test Patient'!G7-$C7)<VisitHrs/24))-1)+('Anita Klesch'!$B7=$B7)*($C7<DayEnd)*($C7+VisitHrs/24>DayStart)+('Anita Klesch'!$C7=$B7)*((($C7+VisitHrs/24>DayEnd)+($C7<DayStart))>0)+('Test Patient 2'!$B7=$B7)*($C7<DayEnd)*($C7+VisitHrs/24>DayStart)+('Test Patient 2'!$C7=$B7)*((($C7+VisitHrs/24>DayEnd)+($C7<DayStart))>0)>=1,1,0),0) -> 0 | K7: =IF(AND($H7=1,$D7<>"",ISNUMBER($E7)),IF(((('Lucy Levene'!B7=$D7)*ISNUMBER('Lucy Levene'!C7)*(ABS('Lucy Levene'!C7-$E7)<VisitHrs/24)+('Lucy Levene'!D7=$D7)*ISNUMBER('Lucy Levene'!E7)*(ABS('Lucy Levene'!E7-$E7)<VisitHrs/24)+('Lucy Levene'!F7=$D7)*ISNUMBER('Lucy Levene'!G7)*(ABS('Lucy Levene'!G7-$E7)<VisitHrs/24)+('Tom Bock'!B7=$D7)*ISNUMBER('Tom Bock'!C7)*(ABS('Tom Bock'!C7-$E7)<VisitHrs/24)+('Tom Bock'!D7=$D7)*ISNUMBER('Tom Bock'!E7)*(ABS('Tom Bock'!E7-$E7)<VisitHrs/24)+('Tom Bock'!F7=$D7)*ISNUMBER('Tom Bock'!G7)*(ABS('Tom Bock'!G7-$E7)<VisitHrs/24)+(Jeremy!B7=$D7)*ISNUMBER(Jeremy!C7)*(ABS(Jeremy!C7-$E7)<VisitHrs/24)+(Jeremy!D7=$D7)*ISNUMBER(Jeremy!E7)*(ABS(Jeremy!E7-$E7)<VisitHrs/24)+(Jeremy!F7=$D7)*ISNUMBER(Jeremy!G7)*(ABS(Jeremy!G7-$E7)<VisitHrs/24)+('Test Patient'!B7=$D7)*ISNUMBER('Test Patient'!C7)*(ABS('Test Patient'!C7-$E7)<VisitHrs/24)+('Test Patient'!D7=$D7)*ISNUMBER('Test Patient'!E7)*(ABS('Test Patient'!E7-$E7)<VisitHrs/24)+('Test Patient'!F7=$D7)*ISNUMBER('Test Patient'!G7)*(ABS('Test Patient'!G7-$E7)<VisitHrs/24))-1)+('Anita Klesch'!$B7=$D7)*($E7<DayEnd)*($E7+VisitHrs/24>DayStart)+('Anita Klesch'!$C7=$D7)*((($E7+VisitHrs/24>DayEnd)+($E7<DayStart))>0)+('Test Patient 2'!$B7=$D7)*($E7<DayEnd)*($E7+VisitHrs/24>DayStart)+('Test Patient 2'!$C7=$D7)*((($E7+VisitHrs/24>DayEnd)+($E7<DayStart))>0)>=1,1,0),0) -> 0 | L7: =IF(AND($H7=1,$F7<>"",ISNUMBER($G7)),IF(((('Lucy Levene'!B7=$F7)*ISNUMBER('Lucy Levene'!C7)*(ABS('Lucy Levene'!C7-$G7)<VisitHrs/24)+('Lucy Levene'!D7=$F7)*ISNUMBER('Lucy Levene'!E7)*(ABS('Lucy Levene'!E7-$G7)<VisitHrs/24)+('Lucy Levene'!F7=$F7)*ISNUMBER('Lucy Levene'!G7)*(ABS('Lucy Levene'!G7-$G7)<VisitHrs/24)+('Tom Bock'!B7=$F7)*ISNUMBER('Tom Bock'!C7)*(ABS('Tom Bock'!C7-$G7)<VisitHrs/24)+('Tom Bock'!D7=$F7)*ISNUMBER('Tom Bock'!E7)*(ABS('Tom Bock'!E7-$G7)<VisitHrs/24)+('Tom Bock'!F7=$F7)*ISNUMBER('Tom Bock'!G7)*(ABS('Tom Bock'!G7-$G7)<VisitHrs/24)+(Jeremy!B7=$F7)*ISNUMBER(Jeremy!C7)*(ABS(Jeremy!C7-$G7)<VisitHrs/24)+(Jeremy!D7=$F7)*ISNUMBER(Jeremy!E7)*(ABS(Jeremy!E7-$G7)<VisitHrs/24)+(Jeremy!F7=$F7)*ISNUMBER(Jeremy!G7)*(ABS(Jeremy!G7-$G7)<VisitHrs/24)+('Test Patient'!B7=$F7)*ISNUMBER('Test Patient'!C7)*(ABS('Test Patient'!C7-$G7)<VisitHrs/24)+('Test Patient'!D7=$F7)*ISNUMBER('Test Patient'!E7)*(ABS('Test Patient'!E7-$G7)<VisitHrs/24)+('Test Patient'!F7=$F7)*ISNUMBER('Test Patient'!G7)*(ABS('Test Patient'!G7-$G7)<VisitHrs/24))-1)+('Anita Klesch'!$B7=$F7)*($G7<DayEnd)*($G7+VisitHrs/24>DayStart)+('Anita Klesch'!$C7=$F7)*((($G7+VisitHrs/24>DayEnd)+($G7<DayStart))>0)+('Test Patient 2'!$B7=$F7)*($G7<DayEnd)*($G7+VisitHrs/24>DayStart)+('Test Patient 2'!$C7=$F7)*((($G7+VisitHrs/24>DayEnd)+($G7<DayStart))>0)>=1,1,0),0) -> 0 | M7: =IF($H7=1,$B7,"") -> Billie | N7: =IF($H7=1,$D7,"") -> Billie | O7: =IF($H7=1,$F7,"") -> 0
A8: =A7+1 -> 46214 | B8: Roderick | D8: Roderick | H8: =IF($A8="",0,IF(AND(OR(NOT(ISNUMBER(LL_Start)),LL_Start=0,$A8>=LL_Start),OR(NOT(ISNUMBER(LL_End)),LL_End=0,$A8<=LL_End)),1,0)) -> 1 | I8: =IF($H8=1,($B8<>"")+($D8<>"")+($F8<>""),0) -> 2 | J8: =IF(AND($H8=1,$B8<>"",ISNUMBER($C8)),IF(((('Lucy Levene'!B8=$B8)*ISNUMBER('Lucy Levene'!C8)*(ABS('Lucy Levene'!C8-$C8)<VisitHrs/24)+('Lucy Levene'!D8=$B8)*ISNUMBER('Lucy Levene'!E8)*(ABS('Lucy Levene'!E8-$C8)<VisitHrs/24)+('Lucy Levene'!F8=$B8)*ISNUMBER('Lucy Levene'!G8)*(ABS('Lucy Levene'!G8-$C8)<VisitHrs/24)+('Tom Bock'!B8=$B8)*ISNUMBER('Tom Bock'!C8)*(ABS('Tom Bock'!C8-$C8)<VisitHrs/24)+('Tom Bock'!D8=$B8)*ISNUMBER('Tom Bock'!E8)*(ABS('Tom Bock'!E8-$C8)<VisitHrs/24)+('Tom Bock'!F8=$B8)*ISNUMBER('Tom Bock'!G8)*(ABS('Tom Bock'!G8-$C8)<VisitHrs/24)+(Jeremy!B8=$B8)*ISNUMBER(Jeremy!C8)*(ABS(Jeremy!C8-$C8)<VisitHrs/24)+(Jeremy!D8=$B8)*ISNUMBER(Jeremy!E8)*(ABS(Jeremy!E8-$C8)<VisitHrs/24)+(Jeremy!F8=$B8)*ISNUMBER(Jeremy!G8)*(ABS(Jeremy!G8-$C8)<VisitHrs/24)+('Test Patient'!B8=$B8)*ISNUMBER('Test Patient'!C8)*(ABS('Test Patient'!C8-$C8)<VisitHrs/24)+('Test Patient'!D8=$B8)*ISNUMBER('Test Patient'!E8)*(ABS('Test Patient'!E8-$C8)<VisitHrs/24)+('Test Patient'!F8=$B8)*ISNUMBER('Test Patient'!G8)*(ABS('Test Patient'!G8-$C8)<VisitHrs/24))-1)+('Anita Klesch'!$B8=$B8)*($C8<DayEnd)*($C8+VisitHrs/24>DayStart)+('Anita Klesch'!$C8=$B8)*((($C8+VisitHrs/24>DayEnd)+($C8<DayStart))>0)+('Test Patient 2'!$B8=$B8)*($C8<DayEnd)*($C8+VisitHrs/24>DayStart)+('Test Patient 2'!$C8=$B8)*((($C8+VisitHrs/24>DayEnd)+($C8<DayStart))>0)>=1,1,0),0) -> 0 | K8: =IF(AND($H8=1,$D8<>"",ISNUMBER($E8)),IF(((('Lucy Levene'!B8=$D8)*ISNUMBER('Lucy Levene'!C8)*(ABS('Lucy Levene'!C8-$E8)<VisitHrs/24)+('Lucy Levene'!D8=$D8)*ISNUMBER('Lucy Levene'!E8)*(ABS('Lucy Levene'!E8-$E8)<VisitHrs/24)+('Lucy Levene'!F8=$D8)*ISNUMBER('Lucy Levene'!G8)*(ABS('Lucy Levene'!G8-$E8)<VisitHrs/24)+('Tom Bock'!B8=$D8)*ISNUMBER('Tom Bock'!C8)*(ABS('Tom Bock'!C8-$E8)<VisitHrs/24)+('Tom Bock'!D8=$D8)*ISNUMBER('Tom Bock'!E8)*(ABS('Tom Bock'!E8-$E8)<VisitHrs/24)+('Tom Bock'!F8=$D8)*ISNUMBER('Tom Bock'!G8)*(ABS('Tom Bock'!G8-$E8)<VisitHrs/24)+(Jeremy!B8=$D8)*ISNUMBER(Jeremy!C8)*(ABS(Jeremy!C8-$E8)<VisitHrs/24)+(Jeremy!D8=$D8)*ISNUMBER(Jeremy!E8)*(ABS(Jeremy!E8-$E8)<VisitHrs/24)+(Jeremy!F8=$D8)*ISNUMBER(Jeremy!G8)*(ABS(Jeremy!G8-$E8)<VisitHrs/24)+('Test Patient'!B8=$D8)*ISNUMBER('Test Patient'!C8)*(ABS('Test Patient'!C8-$E8)<VisitHrs/24)+('Test Patient'!D8=$D8)*ISNUMBER('Test Patient'!E8)*(ABS('Test Patient'!E8-$E8)<VisitHrs/24)+('Test Patient'!F8=$D8)*ISNUMBER('Test Patient'!G8)*(ABS('Test Patient'!G8-$E8)<VisitHrs/24))-1)+('Anita Klesch'!$B8=$D8)*($E8<DayEnd)*($E8+VisitHrs/24>DayStart)+('Anita Klesch'!$C8=$D8)*((($E8+VisitHrs/24>DayEnd)+($E8<DayStart))>0)+('Test Patient 2'!$B8=$D8)*($E8<DayEnd)*($E8+VisitHrs/24>DayStart)+('Test Patient 2'!$C8=$D8)*((($E8+VisitHrs/24>DayEnd)+($E8<DayStart))>0)>=1,1,0),0) -> 0 | L8: =IF(AND($H8=1,$F8<>"",ISNUMBER($G8)),IF(((('Lucy Levene'!B8=$F8)*ISNUMBER('Lucy Levene'!C8)*(ABS('Lucy Levene'!C8-$G8)<VisitHrs/24)+('Lucy Levene'!D8=$F8)*ISNUMBER('Lucy Levene'!E8)*(ABS('Lucy Levene'!E8-$G8)<VisitHrs/24)+('Lucy Levene'!F8=$F8)*ISNUMBER('Lucy Levene'!G8)*(ABS('Lucy Levene'!G8-$G8)<VisitHrs/24)+('Tom Bock'!B8=$F8)*ISNUMBER('Tom Bock'!C8)*(ABS('Tom Bock'!C8-$G8)<VisitHrs/24)+('Tom Bock'!D8=$F8)*ISNUMBER('Tom Bock'!E8)*(ABS('Tom Bock'!E8-$G8)<VisitHrs/24)+('Tom Bock'!F8=$F8)*ISNUMBER('Tom Bock'!G8)*(ABS('Tom Bock'!G8-$G8)<VisitHrs/24)+(Jeremy!B8=$F8)*ISNUMBER(Jeremy!C8)*(ABS(Jeremy!C8-$G8)<VisitHrs/24)+(Jeremy!D8=$F8)*ISNUMBER(Jeremy!E8)*(ABS(Jeremy!E8-$G8)<VisitHrs/24)+(Jeremy!F8=$F8)*ISNUMBER(Jeremy!G8)*(ABS(Jeremy!G8-$G8)<VisitHrs/24)+('Test Patient'!B8=$F8)*ISNUMBER('Test Patient'!C8)*(ABS('Test Patient'!C8-$G8)<VisitHrs/24)+('Test Patient'!D8=$F8)*ISNUMBER('Test Patient'!E8)*(ABS('Test Patient'!E8-$G8)<VisitHrs/24)+('Test Patient'!F8=$F8)*ISNUMBER('Test Patient'!G8)*(ABS('Test Patient'!G8-$G8)<VisitHrs/24))-1)+('Anita Klesch'!$B8=$F8)*($G8<DayEnd)*($G8+VisitHrs/24>DayStart)+('Anita Klesch'!$C8=$F8)*((($G8+VisitHrs/24>DayEnd)+($G8<DayStart))>0)+('Test Patient 2'!$B8=$F8)*($G8<DayEnd)*($G8+VisitHrs/24>DayStart)+('Test Patient 2'!$C8=$F8)*((($G8+VisitHrs/24>DayEnd)+($G8<DayStart))>0)>=1,1,0),0) -> 0 | M8: =IF($H8=1,$B8,"") -> Roderick | N8: =IF($H8=1,$D8,"") -> Roderick | O8: =IF($H8=1,$F8,"") -> 0
A9: =A8+1 -> 46215 | B9: Roderick | D9: Roderick | H9: =IF($A9="",0,IF(AND(OR(NOT(ISNUMBER(LL_Start)),LL_Start=0,$A9>=LL_Start),OR(NOT(ISNUMBER(LL_End)),LL_End=0,$A9<=LL_End)),1,0)) -> 1 | I9: =IF($H9=1,($B9<>"")+($D9<>"")+($F9<>""),0) -> 2 | J9: =IF(AND($H9=1,$B9<>"",ISNUMBER($C9)),IF(((('Lucy Levene'!B9=$B9)*ISNUMBER('Lucy Levene'!C9)*(ABS('Lucy Levene'!C9-$C9)<VisitHrs/24)+('Lucy Levene'!D9=$B9)*ISNUMBER('Lucy Levene'!E9)*(ABS('Lucy Levene'!E9-$C9)<VisitHrs/24)+('Lucy Levene'!F9=$B9)*ISNUMBER('Lucy Levene'!G9)*(ABS('Lucy Levene'!G9-$C9)<VisitHrs/24)+('Tom Bock'!B9=$B9)*ISNUMBER('Tom Bock'!C9)*(ABS('Tom Bock'!C9-$C9)<VisitHrs/24)+('Tom Bock'!D9=$B9)*ISNUMBER('Tom Bock'!E9)*(ABS('Tom Bock'!E9-$C9)<VisitHrs/24)+('Tom Bock'!F9=$B9)*ISNUMBER('Tom Bock'!G9)*(ABS('Tom Bock'!G9-$C9)<VisitHrs/24)+(Jeremy!B9=$B9)*ISNUMBER(Jeremy!C9)*(ABS(Jeremy!C9-$C9)<VisitHrs/24)+(Jeremy!D9=$B9)*ISNUMBER(Jeremy!E9)*(ABS(Jeremy!E9-$C9)<VisitHrs/24)+(Jeremy!F9=$B9)*ISNUMBER(Jeremy!G9)*(ABS(Jeremy!G9-$C9)<VisitHrs/24)+('Test Patient'!B9=$B9)*ISNUMBER('Test Patient'!C9)*(ABS('Test Patient'!C9-$C9)<VisitHrs/24)+('Test Patient'!D9=$B9)*ISNUMBER('Test Patient'!E9)*(ABS('Test Patient'!E9-$C9)<VisitHrs/24)+('Test Patient'!F9=$B9)*ISNUMBER('Test Patient'!G9)*(ABS('Test Patient'!G9-$C9)<VisitHrs/24))-1)+('Anita Klesch'!$B9=$B9)*($C9<DayEnd)*($C9+VisitHrs/24>DayStart)+('Anita Klesch'!$C9=$B9)*((($C9+VisitHrs/24>DayEnd)+($C9<DayStart))>0)+('Test Patient 2'!$B9=$B9)*($C9<DayEnd)*($C9+VisitHrs/24>DayStart)+('Test Patient 2'!$C9=$B9)*((($C9+VisitHrs/24>DayEnd)+($C9<DayStart))>0)>=1,1,0),0) -> 0 | K9: =IF(AND($H9=1,$D9<>"",ISNUMBER($E9)),IF(((('Lucy Levene'!B9=$D9)*ISNUMBER('Lucy Levene'!C9)*(ABS('Lucy Levene'!C9-$E9)<VisitHrs/24)+('Lucy Levene'!D9=$D9)*ISNUMBER('Lucy Levene'!E9)*(ABS('Lucy Levene'!E9-$E9)<VisitHrs/24)+('Lucy Levene'!F9=$D9)*ISNUMBER('Lucy Levene'!G9)*(ABS('Lucy Levene'!G9-$E9)<VisitHrs/24)+('Tom Bock'!B9=$D9)*ISNUMBER('Tom Bock'!C9)*(ABS('Tom Bock'!C9-$E9)<VisitHrs/24)+('Tom Bock'!D9=$D9)*ISNUMBER('Tom Bock'!E9)*(ABS('Tom Bock'!E9-$E9)<VisitHrs/24)+('Tom Bock'!F9=$D9)*ISNUMBER('Tom Bock'!G9)*(ABS('Tom Bock'!G9-$E9)<VisitHrs/24)+(Jeremy!B9=$D9)*ISNUMBER(Jeremy!C9)*(ABS(Jeremy!C9-$E9)<VisitHrs/24)+(Jeremy!D9=$D9)*ISNUMBER(Jeremy!E9)*(ABS(Jeremy!E9-$E9)<VisitHrs/24)+(Jeremy!F9=$D9)*ISNUMBER(Jeremy!G9)*(ABS(Jeremy!G9-$E9)<VisitHrs/24)+('Test Patient'!B9=$D9)*ISNUMBER('Test Patient'!C9)*(ABS('Test Patient'!C9-$E9)<VisitHrs/24)+('Test Patient'!D9=$D9)*ISNUMBER('Test Patient'!E9)*(ABS('Test Patient'!E9-$E9)<VisitHrs/24)+('Test Patient'!F9=$D9)*ISNUMBER('Test Patient'!G9)*(ABS('Test Patient'!G9-$E9)<VisitHrs/24))-1)+('Anita Klesch'!$B9=$D9)*($E9<DayEnd)*($E9+VisitHrs/24>DayStart)+('Anita Klesch'!$C9=$D9)*((($E9+VisitHrs/24>DayEnd)+($E9<DayStart))>0)+('Test Patient 2'!$B9=$D9)*($E9<DayEnd)*($E9+VisitHrs/24>DayStart)+('Test Patient 2'!$C9=$D9)*((($E9+VisitHrs/24>DayEnd)+($E9<DayStart))>0)>=1,1,0),0) -> 0 | L9: =IF(AND($H9=1,$F9<>"",ISNUMBER($G9)),IF(((('Lucy Levene'!B9=$F9)*ISNUMBER('Lucy Levene'!C9)*(ABS('Lucy Levene'!C9-$G9)<VisitHrs/24)+('Lucy Levene'!D9=$F9)*ISNUMBER('Lucy Levene'!E9)*(ABS('Lucy Levene'!E9-$G9)<VisitHrs/24)+('Lucy Levene'!F9=$F9)*ISNUMBER('Lucy Levene'!G9)*(ABS('Lucy Levene'!G9-$G9)<VisitHrs/24)+('Tom Bock'!B9=$F9)*ISNUMBER('Tom Bock'!C9)*(ABS('Tom Bock'!C9-$G9)<VisitHrs/24)+('Tom Bock'!D9=$F9)*ISNUMBER('Tom Bock'!E9)*(ABS('Tom Bock'!E9-$G9)<VisitHrs/24)+('Tom Bock'!F9=$F9)*ISNUMBER('Tom Bock'!G9)*(ABS('Tom Bock'!G9-$G9)<VisitHrs/24)+(Jeremy!B9=$F9)*ISNUMBER(Jeremy!C9)*(ABS(Jeremy!C9-$G9)<VisitHrs/24)+(Jeremy!D9=$F9)*ISNUMBER(Jeremy!E9)*(ABS(Jeremy!E9-$G9)<VisitHrs/24)+(Jeremy!F9=$F9)*ISNUMBER(Jeremy!G9)*(ABS(Jeremy!G9-$G9)<VisitHrs/24)+('Test Patient'!B9=$F9)*ISNUMBER('Test Patient'!C9)*(ABS('Test Patient'!C9-$G9)<VisitHrs/24)+('Test Patient'!D9=$F9)*ISNUMBER('Test Patient'!E9)*(ABS('Test Patient'!E9-$G9)<VisitHrs/24)+('Test Patient'!F9=$F9)*ISNUMBER('Test Patient'!G9)*(ABS('Test Patient'!G9-$G9)<VisitHrs/24))-1)+('Anita Klesch'!$B9=$F9)*($G9<DayEnd)*($G9+VisitHrs/24>DayStart)+('Anita Klesch'!$C9=$F9)*((($G9+VisitHrs/24>DayEnd)+($G9<DayStart))>0)+('Test Patient 2'!$B9=$F9)*($G9<DayEnd)*($G9+VisitHrs/24>DayStart)+('Test Patient 2'!$C9=$F9)*((($G9+VisitHrs/24>DayEnd)+($G9<DayStart))>0)>=1,1,0),0) -> 0 | M9: =IF($H9=1,$B9,"") -> Roderick | N9: =IF($H9=1,$D9,"") -> Roderick | O9: =IF($H9=1,$F9,"") -> 0
